2017-04-03 03:37:10,559 [Thread-2:139991975982848] [django.request:284] [base:handle_uncaught_exception] [ERROR]- Internal Server Error: /index/
Traceback (most recent call last):
  File "/home/lau/anaconda3/lib/python3.5/site-packages/django/core/handlers/base.py", line 149, in get_response
    response = self.process_exception_by_middleware(e, request)
  File "/home/lau/anaconda3/lib/python3.5/site-packages/django/core/handlers/base.py", line 147, in get_response
    response = wrapped_callback(request, *callback_args, **callback_kwargs)
  File "/home/lau/PycharmProjects/django/Nex/ONE/views.py", line 14, in index
    return render(request,'index.html',locals())
  File "/home/lau/anaconda3/lib/python3.5/site-packages/django/shortcuts.py", line 67, in render
    template_name, context, request=request, using=using)
  File "/home/lau/anaconda3/lib/python3.5/site-packages/django/template/loader.py", line 97, in render_to_string
    return template.render(context, request)
  File "/home/lau/anaconda3/lib/python3.5/site-packages/django/template/backends/django.py", line 95, in render
    return self.template.render(context)
  File "/home/lau/anaconda3/lib/python3.5/site-packages/django/template/base.py", line 204, in render
    with context.bind_template(self):
  File "/home/lau/anaconda3/lib/python3.5/contextlib.py", line 59, in __enter__
    return next(self.gen)
  File "/home/lau/anaconda3/lib/python3.5/site-packages/django/template/context.py", line 260, in bind_template
    updates.update(processor(self.request))
TypeError: global_setting() takes 0 positional arguments but 1 was given
2017-04-03 03:38:53,305 [Thread-2:140107568715520] [django.request:284] [base:handle_uncaught_exception] [ERROR]- Internal Server Error: /index/
Traceback (most recent call last):
  File "/home/lau/anaconda3/lib/python3.5/site-packages/django/core/handlers/base.py", line 149, in get_response
    response = self.process_exception_by_middleware(e, request)
  File "/home/lau/anaconda3/lib/python3.5/site-packages/django/core/handlers/base.py", line 147, in get_response
    response = wrapped_callback(request, *callback_args, **callback_kwargs)
  File "/home/lau/PycharmProjects/django/Nex/ONE/views.py", line 14, in index
    return render(request,'index.html',locals())
  File "/home/lau/anaconda3/lib/python3.5/site-packages/django/shortcuts.py", line 67, in render
    template_name, context, request=request, using=using)
  File "/home/lau/anaconda3/lib/python3.5/site-packages/django/template/loader.py", line 97, in render_to_string
    return template.render(context, request)
  File "/home/lau/anaconda3/lib/python3.5/site-packages/django/template/backends/django.py", line 95, in render
    return self.template.render(context)
  File "/home/lau/anaconda3/lib/python3.5/site-packages/django/template/base.py", line 204, in render
    with context.bind_template(self):
  File "/home/lau/anaconda3/lib/python3.5/contextlib.py", line 59, in __enter__
    return next(self.gen)
  File "/home/lau/anaconda3/lib/python3.5/site-packages/django/template/context.py", line 260, in bind_template
    updates.update(processor(self.request))
TypeError: global_setting() takes 0 positional arguments but 1 was given
2017-04-03 03:39:02,468 [Thread-3:140107568715520] [django.request:284] [base:handle_uncaught_exception] [ERROR]- Internal Server Error: /index/
Traceback (most recent call last):
  File "/home/lau/anaconda3/lib/python3.5/site-packages/django/core/handlers/base.py", line 149, in get_response
    response = self.process_exception_by_middleware(e, request)
  File "/home/lau/anaconda3/lib/python3.5/site-packages/django/core/handlers/base.py", line 147, in get_response
    response = wrapped_callback(request, *callback_args, **callback_kwargs)
  File "/home/lau/PycharmProjects/django/Nex/ONE/views.py", line 14, in index
    return render(request,'index.html',locals())
  File "/home/lau/anaconda3/lib/python3.5/site-packages/django/shortcuts.py", line 67, in render
    template_name, context, request=request, using=using)
  File "/home/lau/anaconda3/lib/python3.5/site-packages/django/template/loader.py", line 97, in render_to_string
    return template.render(context, request)
  File "/home/lau/anaconda3/lib/python3.5/site-packages/django/template/backends/django.py", line 95, in render
    return self.template.render(context)
  File "/home/lau/anaconda3/lib/python3.5/site-packages/django/template/base.py", line 204, in render
    with context.bind_template(self):
  File "/home/lau/anaconda3/lib/python3.5/contextlib.py", line 59, in __enter__
    return next(self.gen)
  File "/home/lau/anaconda3/lib/python3.5/site-packages/django/template/context.py", line 260, in bind_template
    updates.update(processor(self.request))
TypeError: global_setting() takes 0 positional arguments but 1 was given
2017-04-03 03:39:03,507 [Thread-4:140107568715520] [django.request:284] [base:handle_uncaught_exception] [ERROR]- Internal Server Error: /index/
Traceback (most recent call last):
  File "/home/lau/anaconda3/lib/python3.5/site-packages/django/core/handlers/base.py", line 149, in get_response
    response = self.process_exception_by_middleware(e, request)
  File "/home/lau/anaconda3/lib/python3.5/site-packages/django/core/handlers/base.py", line 147, in get_response
    response = wrapped_callback(request, *callback_args, **callback_kwargs)
  File "/home/lau/PycharmProjects/django/Nex/ONE/views.py", line 14, in index
    return render(request,'index.html',locals())
  File "/home/lau/anaconda3/lib/python3.5/site-packages/django/shortcuts.py", line 67, in render
    template_name, context, request=request, using=using)
  File "/home/lau/anaconda3/lib/python3.5/site-packages/django/template/loader.py", line 97, in render_to_string
    return template.render(context, request)
  File "/home/lau/anaconda3/lib/python3.5/site-packages/django/template/backends/django.py", line 95, in render
    return self.template.render(context)
  File "/home/lau/anaconda3/lib/python3.5/site-packages/django/template/base.py", line 204, in render
    with context.bind_template(self):
  File "/home/lau/anaconda3/lib/python3.5/contextlib.py", line 59, in __enter__
    return next(self.gen)
  File "/home/lau/anaconda3/lib/python3.5/site-packages/django/template/context.py", line 260, in bind_template
    updates.update(processor(self.request))
TypeError: global_setting() takes 0 positional arguments but 1 was given
2017-04-03 03:39:07,791 [Thread-5:140107568715520] [django.request:284] [base:handle_uncaught_exception] [ERROR]- Internal Server Error: /index/
Traceback (most recent call last):
  File "/home/lau/anaconda3/lib/python3.5/site-packages/django/core/handlers/base.py", line 149, in get_response
    response = self.process_exception_by_middleware(e, request)
  File "/home/lau/anaconda3/lib/python3.5/site-packages/django/core/handlers/base.py", line 147, in get_response
    response = wrapped_callback(request, *callback_args, **callback_kwargs)
  File "/home/lau/PycharmProjects/django/Nex/ONE/views.py", line 14, in index
    return render(request,'index.html',locals())
  File "/home/lau/anaconda3/lib/python3.5/site-packages/django/shortcuts.py", line 67, in render
    template_name, context, request=request, using=using)
  File "/home/lau/anaconda3/lib/python3.5/site-packages/django/template/loader.py", line 97, in render_to_string
    return template.render(context, request)
  File "/home/lau/anaconda3/lib/python3.5/site-packages/django/template/backends/django.py", line 95, in render
    return self.template.render(context)
  File "/home/lau/anaconda3/lib/python3.5/site-packages/django/template/base.py", line 204, in render
    with context.bind_template(self):
  File "/home/lau/anaconda3/lib/python3.5/contextlib.py", line 59, in __enter__
    return next(self.gen)
  File "/home/lau/anaconda3/lib/python3.5/site-packages/django/template/context.py", line 260, in bind_template
    updates.update(processor(self.request))
TypeError: global_setting() takes 0 positional arguments but 1 was given
2017-04-03 07:34:53,480 [Thread-2:140681967834880] [django.request:182] [base:get_response] [WARNING]- Not Found: /
2017-04-03 07:35:01,039 [Thread-19:140681948337920] [django.request:284] [base:handle_uncaught_exception] [ERROR]- Internal Server Error: /admin/
Traceback (most recent call last):
  File "/home/lau/anaconda3/lib/python3.5/site-packages/django/contrib/sessions/backends/base.py", line 196, in _get_session
    return self._session_cache
AttributeError: 'SessionStore' object has no attribute '_session_cache'

During handling of the above exception, another exception occurred:

Traceback (most recent call last):
  File "/home/lau/anaconda3/lib/python3.5/site-packages/django/db/backends/utils.py", line 64, in execute
    return self.cursor.execute(sql, params)
  File "/home/lau/anaconda3/lib/python3.5/site-packages/django/db/backends/mysql/base.py", line 112, in execute
    return self.cursor.execute(query, args)
  File "/home/lau/anaconda3/lib/python3.5/site-packages/pymysql/cursors.py", line 166, in execute
    result = self._query(query)
  File "/home/lau/anaconda3/lib/python3.5/site-packages/pymysql/cursors.py", line 322, in _query
    conn.query(q)
  File "/home/lau/anaconda3/lib/python3.5/site-packages/pymysql/connections.py", line 837, in query
    self._affected_rows = self._read_query_result(unbuffered=unbuffered)
  File "/home/lau/anaconda3/lib/python3.5/site-packages/pymysql/connections.py", line 1021, in _read_query_result
    result.read()
  File "/home/lau/anaconda3/lib/python3.5/site-packages/pymysql/connections.py", line 1304, in read
    first_packet = self.connection._read_packet()
  File "/home/lau/anaconda3/lib/python3.5/site-packages/pymysql/connections.py", line 983, in _read_packet
    packet.check_error()
  File "/home/lau/anaconda3/lib/python3.5/site-packages/pymysql/connections.py", line 395, in check_error
    err.raise_mysql_exception(self._data)
  File "/home/lau/anaconda3/lib/python3.5/site-packages/pymysql/err.py", line 102, in raise_mysql_exception
    raise errorclass(errno, errval)
pymysql.err.ProgrammingError: (1146, "42S02Table 'Nex.django_session' doesn't exist")

The above exception was the direct cause of the following exception:

Traceback (most recent call last):
  File "/home/lau/anaconda3/lib/python3.5/site-packages/django/core/handlers/base.py", line 149, in get_response
    response = self.process_exception_by_middleware(e, request)
  File "/home/lau/anaconda3/lib/python3.5/site-packages/django/core/handlers/base.py", line 147, in get_response
    response = wrapped_callback(request, *callback_args, **callback_kwargs)
  File "/home/lau/anaconda3/lib/python3.5/site-packages/django/contrib/admin/sites.py", line 265, in wrapper
    return self.admin_view(view, cacheable)(*args, **kwargs)
  File "/home/lau/anaconda3/lib/python3.5/site-packages/django/utils/decorators.py", line 149, in _wrapped_view
    response = view_func(request, *args, **kwargs)
  File "/home/lau/anaconda3/lib/python3.5/site-packages/django/views/decorators/cache.py", line 57, in _wrapped_view_func
    response = view_func(request, *args, **kwargs)
  File "/home/lau/anaconda3/lib/python3.5/site-packages/django/contrib/admin/sites.py", line 233, in inner
    if not self.has_permission(request):
  File "/home/lau/anaconda3/lib/python3.5/site-packages/django/contrib/admin/sites.py", line 173, in has_permission
    return request.user.is_active and request.user.is_staff
  File "/home/lau/anaconda3/lib/python3.5/site-packages/django/utils/functional.py", line 204, in inner
    self._setup()
  File "/home/lau/anaconda3/lib/python3.5/site-packages/django/utils/functional.py", line 351, in _setup
    self._wrapped = self._setupfunc()
  File "/home/lau/anaconda3/lib/python3.5/site-packages/django/contrib/auth/middleware.py", line 22, in <lambda>
    request.user = SimpleLazyObject(lambda: get_user(request))
  File "/home/lau/anaconda3/lib/python3.5/site-packages/django/contrib/auth/middleware.py", line 10, in get_user
    request._cached_user = auth.get_user(request)
  File "/home/lau/anaconda3/lib/python3.5/site-packages/django/contrib/auth/__init__.py", line 167, in get_user
    user_id = _get_user_session_key(request)
  File "/home/lau/anaconda3/lib/python3.5/site-packages/django/contrib/auth/__init__.py", line 59, in _get_user_session_key
    return get_user_model()._meta.pk.to_python(request.session[SESSION_KEY])
  File "/home/lau/anaconda3/lib/python3.5/site-packages/django/contrib/sessions/backends/base.py", line 50, in __getitem__
    return self._session[key]
  File "/home/lau/anaconda3/lib/python3.5/site-packages/django/contrib/sessions/backends/base.py", line 201, in _get_session
    self._session_cache = self.load()
  File "/home/lau/anaconda3/lib/python3.5/site-packages/django/contrib/sessions/backends/db.py", line 33, in load
    expire_date__gt=timezone.now()
  File "/home/lau/anaconda3/lib/python3.5/site-packages/django/db/models/manager.py", line 122, in manager_method
    return getattr(self.get_queryset(), name)(*args, **kwargs)
  File "/home/lau/anaconda3/lib/python3.5/site-packages/django/db/models/query.py", line 381, in get
    num = len(clone)
  File "/home/lau/anaconda3/lib/python3.5/site-packages/django/db/models/query.py", line 240, in __len__
    self._fetch_all()
  File "/home/lau/anaconda3/lib/python3.5/site-packages/django/db/models/query.py", line 1074, in _fetch_all
    self._result_cache = list(self.iterator())
  File "/home/lau/anaconda3/lib/python3.5/site-packages/django/db/models/query.py", line 52, in __iter__
    results = compiler.execute_sql()
  File "/home/lau/anaconda3/lib/python3.5/site-packages/django/db/models/sql/compiler.py", line 848, in execute_sql
    cursor.execute(sql, params)
  File "/home/lau/anaconda3/lib/python3.5/site-packages/django/db/backends/utils.py", line 79, in execute
    return super(CursorDebugWrapper, self).execute(sql, params)
  File "/home/lau/anaconda3/lib/python3.5/site-packages/django/db/backends/utils.py", line 64, in execute
    return self.cursor.execute(sql, params)
  File "/home/lau/anaconda3/lib/python3.5/site-packages/django/db/utils.py", line 95, in __exit__
    six.reraise(dj_exc_type, dj_exc_value, traceback)
  File "/home/lau/anaconda3/lib/python3.5/site-packages/django/utils/six.py", line 685, in reraise
    raise value.with_traceback(tb)
  File "/home/lau/anaconda3/lib/python3.5/site-packages/django/db/backends/utils.py", line 64, in execute
    return self.cursor.execute(sql, params)
  File "/home/lau/anaconda3/lib/python3.5/site-packages/django/db/backends/mysql/base.py", line 112, in execute
    return self.cursor.execute(query, args)
  File "/home/lau/anaconda3/lib/python3.5/site-packages/pymysql/cursors.py", line 166, in execute
    result = self._query(query)
  File "/home/lau/anaconda3/lib/python3.5/site-packages/pymysql/cursors.py", line 322, in _query
    conn.query(q)
  File "/home/lau/anaconda3/lib/python3.5/site-packages/pymysql/connections.py", line 837, in query
    self._affected_rows = self._read_query_result(unbuffered=unbuffered)
  File "/home/lau/anaconda3/lib/python3.5/site-packages/pymysql/connections.py", line 1021, in _read_query_result
    result.read()
  File "/home/lau/anaconda3/lib/python3.5/site-packages/pymysql/connections.py", line 1304, in read
    first_packet = self.connection._read_packet()
  File "/home/lau/anaconda3/lib/python3.5/site-packages/pymysql/connections.py", line 983, in _read_packet
    packet.check_error()
  File "/home/lau/anaconda3/lib/python3.5/site-packages/pymysql/connections.py", line 395, in check_error
    err.raise_mysql_exception(self._data)
  File "/home/lau/anaconda3/lib/python3.5/site-packages/pymysql/err.py", line 102, in raise_mysql_exception
    raise errorclass(errno, errval)
django.db.utils.ProgrammingError: (1146, "42S02Table 'Nex.django_session' doesn't exist")
2017-04-03 07:39:15,409 [Thread-2:140193131681536] [django.request:182] [base:get_response] [WARNING]- Not Found: /
2017-04-03 07:49:44,525 [Thread-93:140054722770688] [django.request:182] [base:get_response] [WARNING]- Not Found: /
2017-04-03 07:52:11,123 [Thread-26:140359363442432] [django.request:284] [base:handle_uncaught_exception] [ERROR]- Internal Server Error: /admin/ONE/article/add/
Traceback (most recent call last):
  File "/home/lau/anaconda3/lib/python3.5/site-packages/django/contrib/admin/options.py", line 639, in get_form
    return modelform_factory(self.model, **defaults)
  File "/home/lau/anaconda3/lib/python3.5/site-packages/django/forms/models.py", line 545, in modelform_factory
    return type(form)(class_name, (form,), form_class_attrs)
  File "/home/lau/anaconda3/lib/python3.5/site-packages/django/forms/models.py", line 257, in __new__
    raise FieldError(message)
django.core.exceptions.FieldError: Unknown field(s) (name) specified for Article

During handling of the above exception, another exception occurred:

Traceback (most recent call last):
  File "/home/lau/anaconda3/lib/python3.5/site-packages/django/core/handlers/base.py", line 149, in get_response
    response = self.process_exception_by_middleware(e, request)
  File "/home/lau/anaconda3/lib/python3.5/site-packages/django/core/handlers/base.py", line 147, in get_response
    response = wrapped_callback(request, *callback_args, **callback_kwargs)
  File "/home/lau/anaconda3/lib/python3.5/site-packages/django/contrib/admin/options.py", line 541, in wrapper
    return self.admin_site.admin_view(view)(*args, **kwargs)
  File "/home/lau/anaconda3/lib/python3.5/site-packages/django/utils/decorators.py", line 149, in _wrapped_view
    response = view_func(request, *args, **kwargs)
  File "/home/lau/anaconda3/lib/python3.5/site-packages/django/views/decorators/cache.py", line 57, in _wrapped_view_func
    response = view_func(request, *args, **kwargs)
  File "/home/lau/anaconda3/lib/python3.5/site-packages/django/contrib/admin/sites.py", line 244, in inner
    return view(request, *args, **kwargs)
  File "/home/lau/anaconda3/lib/python3.5/site-packages/django/contrib/admin/options.py", line 1437, in add_view
    return self.changeform_view(request, None, form_url, extra_context)
  File "/home/lau/anaconda3/lib/python3.5/site-packages/django/utils/decorators.py", line 67, in _wrapper
    return bound_func(*args, **kwargs)
  File "/home/lau/anaconda3/lib/python3.5/site-packages/django/utils/decorators.py", line 149, in _wrapped_view
    response = view_func(request, *args, **kwargs)
  File "/home/lau/anaconda3/lib/python3.5/site-packages/django/utils/decorators.py", line 63, in bound_func
    return func.__get__(self, type(self))(*args2, **kwargs2)
  File "/home/lau/anaconda3/lib/python3.5/contextlib.py", line 30, in inner
    return func(*args, **kwds)
  File "/home/lau/anaconda3/lib/python3.5/site-packages/django/contrib/admin/options.py", line 1367, in changeform_view
    ModelForm = self.get_form(request, obj)
  File "/home/lau/anaconda3/lib/python3.5/site-packages/django/contrib/admin/options.py", line 642, in get_form
    % (e, self.__class__.__name__))
django.core.exceptions.FieldError: Unknown field(s) (name) specified for Article. Check fields/fieldsets/exclude attributes of class ArticleAdmin.
2017-04-03 09:14:05,306 [Thread-45:139658608203520] [django.request:284] [base:handle_uncaught_exception] [ERROR]- Internal Server Error: /admin/ONE/article/add/
Traceback (most recent call last):
  File "/home/lau/anaconda3/lib/python3.5/site-packages/django/db/backends/utils.py", line 64, in execute
    return self.cursor.execute(sql, params)
  File "/home/lau/anaconda3/lib/python3.5/site-packages/django/db/backends/mysql/base.py", line 112, in execute
    return self.cursor.execute(query, args)
  File "/home/lau/anaconda3/lib/python3.5/site-packages/pymysql/cursors.py", line 166, in execute
    result = self._query(query)
  File "/home/lau/anaconda3/lib/python3.5/site-packages/pymysql/cursors.py", line 322, in _query
    conn.query(q)
  File "/home/lau/anaconda3/lib/python3.5/site-packages/pymysql/connections.py", line 837, in query
    self._affected_rows = self._read_query_result(unbuffered=unbuffered)
  File "/home/lau/anaconda3/lib/python3.5/site-packages/pymysql/connections.py", line 1021, in _read_query_result
    result.read()
  File "/home/lau/anaconda3/lib/python3.5/site-packages/pymysql/connections.py", line 1304, in read
    first_packet = self.connection._read_packet()
  File "/home/lau/anaconda3/lib/python3.5/site-packages/pymysql/connections.py", line 983, in _read_packet
    packet.check_error()
  File "/home/lau/anaconda3/lib/python3.5/site-packages/pymysql/connections.py", line 395, in check_error
    err.raise_mysql_exception(self._data)
  File "/home/lau/anaconda3/lib/python3.5/site-packages/pymysql/err.py", line 102, in raise_mysql_exception
    raise errorclass(errno, errval)
pymysql.err.IntegrityError: (1048, "23000Column 'user_id' cannot be null")

The above exception was the direct cause of the following exception:

Traceback (most recent call last):
  File "/home/lau/anaconda3/lib/python3.5/site-packages/django/core/handlers/base.py", line 149, in get_response
    response = self.process_exception_by_middleware(e, request)
  File "/home/lau/anaconda3/lib/python3.5/site-packages/django/core/handlers/base.py", line 147, in get_response
    response = wrapped_callback(request, *callback_args, **callback_kwargs)
  File "/home/lau/anaconda3/lib/python3.5/site-packages/django/contrib/admin/options.py", line 541, in wrapper
    return self.admin_site.admin_view(view)(*args, **kwargs)
  File "/home/lau/anaconda3/lib/python3.5/site-packages/django/utils/decorators.py", line 149, in _wrapped_view
    response = view_func(request, *args, **kwargs)
  File "/home/lau/anaconda3/lib/python3.5/site-packages/django/views/decorators/cache.py", line 57, in _wrapped_view_func
    response = view_func(request, *args, **kwargs)
  File "/home/lau/anaconda3/lib/python3.5/site-packages/django/contrib/admin/sites.py", line 244, in inner
    return view(request, *args, **kwargs)
  File "/home/lau/anaconda3/lib/python3.5/site-packages/django/contrib/admin/options.py", line 1437, in add_view
    return self.changeform_view(request, None, form_url, extra_context)
  File "/home/lau/anaconda3/lib/python3.5/site-packages/django/utils/decorators.py", line 67, in _wrapper
    return bound_func(*args, **kwargs)
  File "/home/lau/anaconda3/lib/python3.5/site-packages/django/utils/decorators.py", line 149, in _wrapped_view
    response = view_func(request, *args, **kwargs)
  File "/home/lau/anaconda3/lib/python3.5/site-packages/django/utils/decorators.py", line 63, in bound_func
    return func.__get__(self, type(self))(*args2, **kwargs2)
  File "/home/lau/anaconda3/lib/python3.5/contextlib.py", line 30, in inner
    return func(*args, **kwds)
  File "/home/lau/anaconda3/lib/python3.5/site-packages/django/contrib/admin/options.py", line 1378, in changeform_view
    self.save_model(request, new_object, form, not add)
  File "/home/lau/anaconda3/lib/python3.5/site-packages/django/contrib/admin/options.py", line 991, in save_model
    obj.save()
  File "/home/lau/anaconda3/lib/python3.5/site-packages/django/db/models/base.py", line 708, in save
    force_update=force_update, update_fields=update_fields)
  File "/home/lau/anaconda3/lib/python3.5/site-packages/django/db/models/base.py", line 736, in save_base
    updated = self._save_table(raw, cls, force_insert, force_update, using, update_fields)
  File "/home/lau/anaconda3/lib/python3.5/site-packages/django/db/models/base.py", line 820, in _save_table
    result = self._do_insert(cls._base_manager, using, fields, update_pk, raw)
  File "/home/lau/anaconda3/lib/python3.5/site-packages/django/db/models/base.py", line 859, in _do_insert
    using=using, raw=raw)
  File "/home/lau/anaconda3/lib/python3.5/site-packages/django/db/models/manager.py", line 122, in manager_method
    return getattr(self.get_queryset(), name)(*args, **kwargs)
  File "/home/lau/anaconda3/lib/python3.5/site-packages/django/db/models/query.py", line 1039, in _insert
    return query.get_compiler(using=using).execute_sql(return_id)
  File "/home/lau/anaconda3/lib/python3.5/site-packages/django/db/models/sql/compiler.py", line 1060, in execute_sql
    cursor.execute(sql, params)
  File "/home/lau/anaconda3/lib/python3.5/site-packages/django/db/backends/utils.py", line 79, in execute
    return super(CursorDebugWrapper, self).execute(sql, params)
  File "/home/lau/anaconda3/lib/python3.5/site-packages/django/db/backends/utils.py", line 64, in execute
    return self.cursor.execute(sql, params)
  File "/home/lau/anaconda3/lib/python3.5/site-packages/django/db/utils.py", line 95, in __exit__
    six.reraise(dj_exc_type, dj_exc_value, traceback)
  File "/home/lau/anaconda3/lib/python3.5/site-packages/django/utils/six.py", line 685, in reraise
    raise value.with_traceback(tb)
  File "/home/lau/anaconda3/lib/python3.5/site-packages/django/db/backends/utils.py", line 64, in execute
    return self.cursor.execute(sql, params)
  File "/home/lau/anaconda3/lib/python3.5/site-packages/django/db/backends/mysql/base.py", line 112, in execute
    return self.cursor.execute(query, args)
  File "/home/lau/anaconda3/lib/python3.5/site-packages/pymysql/cursors.py", line 166, in execute
    result = self._query(query)
  File "/home/lau/anaconda3/lib/python3.5/site-packages/pymysql/cursors.py", line 322, in _query
    conn.query(q)
  File "/home/lau/anaconda3/lib/python3.5/site-packages/pymysql/connections.py", line 837, in query
    self._affected_rows = self._read_query_result(unbuffered=unbuffered)
  File "/home/lau/anaconda3/lib/python3.5/site-packages/pymysql/connections.py", line 1021, in _read_query_result
    result.read()
  File "/home/lau/anaconda3/lib/python3.5/site-packages/pymysql/connections.py", line 1304, in read
    first_packet = self.connection._read_packet()
  File "/home/lau/anaconda3/lib/python3.5/site-packages/pymysql/connections.py", line 983, in _read_packet
    packet.check_error()
  File "/home/lau/anaconda3/lib/python3.5/site-packages/pymysql/connections.py", line 395, in check_error
    err.raise_mysql_exception(self._data)
  File "/home/lau/anaconda3/lib/python3.5/site-packages/pymysql/err.py", line 102, in raise_mysql_exception
    raise errorclass(errno, errval)
django.db.utils.IntegrityError: (1048, "23000Column 'user_id' cannot be null")
2017-04-03 09:19:43,816 [Thread-51:140270410659584] [django.request:284] [base:handle_uncaught_exception] [ERROR]- Internal Server Error: /admin/ONE/article/add/
Traceback (most recent call last):
  File "/home/lau/anaconda3/lib/python3.5/site-packages/django/db/backends/utils.py", line 64, in execute
    return self.cursor.execute(sql, params)
  File "/home/lau/anaconda3/lib/python3.5/site-packages/django/db/backends/mysql/base.py", line 112, in execute
    return self.cursor.execute(query, args)
  File "/home/lau/anaconda3/lib/python3.5/site-packages/pymysql/cursors.py", line 166, in execute
    result = self._query(query)
  File "/home/lau/anaconda3/lib/python3.5/site-packages/pymysql/cursors.py", line 322, in _query
    conn.query(q)
  File "/home/lau/anaconda3/lib/python3.5/site-packages/pymysql/connections.py", line 837, in query
    self._affected_rows = self._read_query_result(unbuffered=unbuffered)
  File "/home/lau/anaconda3/lib/python3.5/site-packages/pymysql/connections.py", line 1021, in _read_query_result
    result.read()
  File "/home/lau/anaconda3/lib/python3.5/site-packages/pymysql/connections.py", line 1304, in read
    first_packet = self.connection._read_packet()
  File "/home/lau/anaconda3/lib/python3.5/site-packages/pymysql/connections.py", line 983, in _read_packet
    packet.check_error()
  File "/home/lau/anaconda3/lib/python3.5/site-packages/pymysql/connections.py", line 395, in check_error
    err.raise_mysql_exception(self._data)
  File "/home/lau/anaconda3/lib/python3.5/site-packages/pymysql/err.py", line 102, in raise_mysql_exception
    raise errorclass(errno, errval)
pymysql.err.IntegrityError: (1048, "23000Column 'user_id' cannot be null")

The above exception was the direct cause of the following exception:

Traceback (most recent call last):
  File "/home/lau/anaconda3/lib/python3.5/site-packages/django/core/handlers/base.py", line 149, in get_response
    response = self.process_exception_by_middleware(e, request)
  File "/home/lau/anaconda3/lib/python3.5/site-packages/django/core/handlers/base.py", line 147, in get_response
    response = wrapped_callback(request, *callback_args, **callback_kwargs)
  File "/home/lau/anaconda3/lib/python3.5/site-packages/django/contrib/admin/options.py", line 541, in wrapper
    return self.admin_site.admin_view(view)(*args, **kwargs)
  File "/home/lau/anaconda3/lib/python3.5/site-packages/django/utils/decorators.py", line 149, in _wrapped_view
    response = view_func(request, *args, **kwargs)
  File "/home/lau/anaconda3/lib/python3.5/site-packages/django/views/decorators/cache.py", line 57, in _wrapped_view_func
    response = view_func(request, *args, **kwargs)
  File "/home/lau/anaconda3/lib/python3.5/site-packages/django/contrib/admin/sites.py", line 244, in inner
    return view(request, *args, **kwargs)
  File "/home/lau/anaconda3/lib/python3.5/site-packages/django/contrib/admin/options.py", line 1437, in add_view
    return self.changeform_view(request, None, form_url, extra_context)
  File "/home/lau/anaconda3/lib/python3.5/site-packages/django/utils/decorators.py", line 67, in _wrapper
    return bound_func(*args, **kwargs)
  File "/home/lau/anaconda3/lib/python3.5/site-packages/django/utils/decorators.py", line 149, in _wrapped_view
    response = view_func(request, *args, **kwargs)
  File "/home/lau/anaconda3/lib/python3.5/site-packages/django/utils/decorators.py", line 63, in bound_func
    return func.__get__(self, type(self))(*args2, **kwargs2)
  File "/home/lau/anaconda3/lib/python3.5/contextlib.py", line 30, in inner
    return func(*args, **kwds)
  File "/home/lau/anaconda3/lib/python3.5/site-packages/django/contrib/admin/options.py", line 1378, in changeform_view
    self.save_model(request, new_object, form, not add)
  File "/home/lau/anaconda3/lib/python3.5/site-packages/django/contrib/admin/options.py", line 991, in save_model
    obj.save()
  File "/home/lau/anaconda3/lib/python3.5/site-packages/django/db/models/base.py", line 708, in save
    force_update=force_update, update_fields=update_fields)
  File "/home/lau/anaconda3/lib/python3.5/site-packages/django/db/models/base.py", line 736, in save_base
    updated = self._save_table(raw, cls, force_insert, force_update, using, update_fields)
  File "/home/lau/anaconda3/lib/python3.5/site-packages/django/db/models/base.py", line 820, in _save_table
    result = self._do_insert(cls._base_manager, using, fields, update_pk, raw)
  File "/home/lau/anaconda3/lib/python3.5/site-packages/django/db/models/base.py", line 859, in _do_insert
    using=using, raw=raw)
  File "/home/lau/anaconda3/lib/python3.5/site-packages/django/db/models/manager.py", line 122, in manager_method
    return getattr(self.get_queryset(), name)(*args, **kwargs)
  File "/home/lau/anaconda3/lib/python3.5/site-packages/django/db/models/query.py", line 1039, in _insert
    return query.get_compiler(using=using).execute_sql(return_id)
  File "/home/lau/anaconda3/lib/python3.5/site-packages/django/db/models/sql/compiler.py", line 1060, in execute_sql
    cursor.execute(sql, params)
  File "/home/lau/anaconda3/lib/python3.5/site-packages/django/db/backends/utils.py", line 79, in execute
    return super(CursorDebugWrapper, self).execute(sql, params)
  File "/home/lau/anaconda3/lib/python3.5/site-packages/django/db/backends/utils.py", line 64, in execute
    return self.cursor.execute(sql, params)
  File "/home/lau/anaconda3/lib/python3.5/site-packages/django/db/utils.py", line 95, in __exit__
    six.reraise(dj_exc_type, dj_exc_value, traceback)
  File "/home/lau/anaconda3/lib/python3.5/site-packages/django/utils/six.py", line 685, in reraise
    raise value.with_traceback(tb)
  File "/home/lau/anaconda3/lib/python3.5/site-packages/django/db/backends/utils.py", line 64, in execute
    return self.cursor.execute(sql, params)
  File "/home/lau/anaconda3/lib/python3.5/site-packages/django/db/backends/mysql/base.py", line 112, in execute
    return self.cursor.execute(query, args)
  File "/home/lau/anaconda3/lib/python3.5/site-packages/pymysql/cursors.py", line 166, in execute
    result = self._query(query)
  File "/home/lau/anaconda3/lib/python3.5/site-packages/pymysql/cursors.py", line 322, in _query
    conn.query(q)
  File "/home/lau/anaconda3/lib/python3.5/site-packages/pymysql/connections.py", line 837, in query
    self._affected_rows = self._read_query_result(unbuffered=unbuffered)
  File "/home/lau/anaconda3/lib/python3.5/site-packages/pymysql/connections.py", line 1021, in _read_query_result
    result.read()
  File "/home/lau/anaconda3/lib/python3.5/site-packages/pymysql/connections.py", line 1304, in read
    first_packet = self.connection._read_packet()
  File "/home/lau/anaconda3/lib/python3.5/site-packages/pymysql/connections.py", line 983, in _read_packet
    packet.check_error()
  File "/home/lau/anaconda3/lib/python3.5/site-packages/pymysql/connections.py", line 395, in check_error
    err.raise_mysql_exception(self._data)
  File "/home/lau/anaconda3/lib/python3.5/site-packages/pymysql/err.py", line 102, in raise_mysql_exception
    raise errorclass(errno, errval)
django.db.utils.IntegrityError: (1048, "23000Column 'user_id' cannot be null")
